2025-01-08 17:34:00,574 - ERROR - Ошибка при обработке результата: 'url_name'
Traceback (most recent call last):
  File "C:\Users\New\Documents\GitHub\WarframeMarketAnalysys\WarframeMarketDataCollector.py", line 114, in main
    all_items_data[item_data['url_name']] = item_data
                   ~~~~~~~~~^^^^^^^^^^^^
KeyError: 'url_name'
2025-01-08 17:34:00,578 - WARNING - Получена ошибка 429 для brute_conditioning, повтор через 1 секунд (попытка 1).
2025-01-08 17:34:00,607 - INFO - Успешно получены данные для предмета: elusive_posture
2025-01-08 17:34:00,608 - ERROR - Ошибка при обработке результата: 'url_name'
Traceback (most recent call last):
  File "C:\Users\New\Documents\GitHub\WarframeMarketAnalysys\WarframeMarketDataCollector.py", line 114, in main
    all_items_data[item_data['url_name']] = item_data
                   ~~~~~~~~~^^^^^^^^^^^^
KeyError: 'url_name'
2025-01-08 17:34:00,620 - WARNING - Получена ошибка 429 для galvanized_steel, повтор через 1 секунд (попытка 1).
2025-01-08 17:34:00,629 - WARNING - Получена ошибка 429 для balanced_posture, повтор через 1 секунд (попытка 2).
2025-01-08 17:34:00,631 - WARNING - Получена ошибка 429 для sevagoth_prime_chassis_blueprint, повтор через 1 секунд (попытка 5).
2025-01-08 17:34:00,657 - WARNING - Получена ошибка 429 для galvanized_reflex, повтор через 1 секунд (попытка 1).
2025-01-08 17:34:00,664 - WARNING - Получена ошибка 429 для prey_of_dynar, повтор через 1 секунд (попытка 3).
2025-01-08 17:34:00,673 - WARNING - Получена ошибка 429 для lith_d6_relic, повтор через 1 секунд (попытка 1).
2025-01-08 17:34:00,686 - WARNING - Получена ошибка 429 для resourceful_retriever, повтор через 1 секунд (попытка 2).
2025-01-08 17:34:00,721 - INFO - Успешно получены данные для предмета: galvanized_elementalist
2025-01-08 17:34:00,722 - ERROR - Ошибка при обработке результата: 'url_name'
Traceback (most recent call last):
  File "C:\Users\New\Documents\GitHub\WarframeMarketAnalysys\WarframeMarketDataCollector.py", line 114, in main
    all_items_data[item_data['url_name']] = item_data
                   ~~~~~~~~~^^^^^^^^^^^^
KeyError: 'url_name'
2025-01-08 17:34:00,727 - WARNING - Получена ошибка 429 для axi_s16_relic, повтор через 1 секунд (попытка 5).
2025-01-08 17:34:00,742 - WARNING - Получена ошибка 429 для aegis_gale, повтор через 1 секунд (попытка 3).
2025-01-08 17:34:00,746 - WARNING - Получена ошибка 429 для meso_h8_relic, повтор через 1 секунд (попытка 1).
2025-01-08 17:34:00,834 - ERROR - Не удалось получить данные для akmagnus_prime_link после 5 попыток. Превышено количество попыток.
2025-01-08 17:34:00,834 - WARNING - Получены пустые данные для предмета.
2025-01-08 17:34:00,913 - WARNING - Получена ошибка 429 для gastro, повтор через 1 секунд (попытка 3).
2025-01-08 17:34:00,926 - WARNING - Получена ошибка 429 для neo_k8_relic, повтор через 1 секунд (попытка 1).
2025-01-08 17:34:00,952 - WARNING - Получена ошибка 429 для neo_c5_relic, повтор через 1 секунд (попытка 1).
2025-01-08 17:34:00,958 - WARNING - Получена ошибка 429 для lith_n15_relic, повтор через 1 секунд (попытка 4).
2025-01-08 17:34:00,983 - WARNING - Получена ошибка 429 для lith_g12_relic, повтор через 1 секунд (попытка 4).
2025-01-08 17:34:01,037 - WARNING - Получена ошибка 429 для higasa_serration, повтор через 1 секунд (попытка 3).
2025-01-08 17:34:01,040 - INFO - Успешно получены данные для предмета: coil_recharge
2025-01-08 17:34:01,040 - ERROR - Ошибка при обработке результата: 'url_name'
Traceback (most recent call last):
  File "C:\Users\New\Documents\GitHub\WarframeMarketAnalysys\WarframeMarketDataCollector.py", line 114, in main
    all_items_data[item_data['url_name']] = item_data
                   ~~~~~~~~~^^^^^^^^^^^^
KeyError: 'url_name'
2025-01-08 17:34:01,054 - WARNING - Получена ошибка 429 для prosperous_retriever, повтор через 1 секунд (попытка 2).
2025-01-08 17:34:01,054 - ERROR - Не удалось получить данные для sevagoth_prime_set после 5 попыток. Превышено количество попыток.
2025-01-08 17:34:01,055 - WARNING - Получены пустые данные для предмета.
2025-01-08 17:34:01,061 - WARNING - Получена ошибка 429 для neo_z11_relic, повтор через 1 секунд (попытка 5).
2025-01-08 17:34:01,146 - WARNING - Получена ошибка 429 для axi_g13_relic, повтор через 1 секунд (попытка 1).
2025-01-08 17:34:01,148 - WARNING - Получена ошибка 429 для epitaph_prime_set, повтор через 1 секунд (попытка 4).
2025-01-08 17:34:01,185 - WARNING - Получена ошибка 429 для neo_p7_relic, повтор через 1 секунд (попытка 5).
2025-01-08 17:34:01,186 - WARNING - Получена ошибка 429 для immunity_resistance, повтор через 1 секунд (попытка 2).
2025-01-08 17:34:01,189 - WARNING - Получена ошибка 429 для sepsis_claws, повтор через 1 секунд (попытка 3).
2025-01-08 17:34:01,195 - INFO - Успешно получены данные для предмета: axi_n11_relic
2025-01-08 17:34:01,196 - ERROR - Ошибка при обработке результата: 'url_name'
Traceback (most recent call last):
  File "C:\Users\New\Documents\GitHub\WarframeMarketAnalysys\WarframeMarketDataCollector.py", line 114, in main
    all_items_data[item_data['url_name']] = item_data
                   ~~~~~~~~~^^^^^^^^^^^^
KeyError: 'url_name'
2025-01-08 17:34:01,290 - WARNING - Получена ошибка 429 для xaku_prime_set, повтор через 1 секунд (попытка 1).
2025-01-08 17:34:01,297 - WARNING - Получена ошибка 429 для amanata_pressure, повтор через 1 секунд (попытка 3).
2025-01-08 17:34:01,354 - WARNING - Получена ошибка 429 для nautilus_prime_set, повтор через 1 секунд (попытка 4).
2025-01-08 17:34:01,377 - WARNING - Получена ошибка 429 для disabling_conditioning, повтор через 1 секунд (попытка 2).
2025-01-08 17:34:01,387 - WARNING - Получена ошибка 429 для precision_conditioning, повтор через 1 секунд (попытка 2).
2025-01-08 17:34:01,396 - WARNING - Получена ошибка 429 для bloodthirst, повтор через 1 секунд (попытка 2).
2025-01-08 17:34:01,434 - INFO - Успешно получены данные для предмета: magnetic_strike
2025-01-08 17:34:01,435 - ERROR - Ошибка при обработке результата: 'url_name'
Traceback (most recent call last):
  File "C:\Users\New\Documents\GitHub\WarframeMarketAnalysys\WarframeMarketDataCollector.py", line 114, in main
    all_items_data[item_data['url_name']] = item_data
                   ~~~~~~~~~^^^^^^^^^^^^
KeyError: 'url_name'
2025-01-08 17:34:01,453 - WARNING - Получена ошибка 429 для neo_e4_relic, повтор через 1 секунд (попытка 5).
2025-01-08 17:34:01,456 - WARNING - Получена ошибка 429 для meso_f5_relic, повтор через 1 секунд (попытка 5).
2025-01-08 17:34:01,469 - ERROR - Не удалось получить данные для sevagoth_prime_neuroptics_blueprint после 5 попыток. Превышено количество попыток.
2025-01-08 17:34:01,469 - WARNING - Получены пустые данные для предмета.
2025-01-08 17:34:01,496 - WARNING - Получена ошибка 429 для chilling_claws, повтор через 1 секунд (попытка 3).
2025-01-08 17:34:01,542 - WARNING - Получена ошибка 429 для xaku_prime_blueprint, повтор через 1 секунд (попытка 1).
2025-01-08 17:34:01,548 - WARNING - Получена ошибка 429 для bell_ringer, повтор через 1 секунд (попытка 2).
2025-01-08 17:34:01,562 - WARNING - Получена ошибка 429 для frenzied_posture, повтор через 1 секунд (попытка 3).
2025-01-08 17:34:01,574 - WARNING - Получена ошибка 429 для nautilus_prime_carapace, повтор через 1 секунд (попытка 4).
2025-01-08 17:34:01,576 - WARNING - Получена ошибка 429 для epitaph_prime_receiver, повтор через 1 секунд (попытка 4).
2025-01-08 17:34:01,582 - WARNING - Получена ошибка 429 для epitaph_prime_barrel, повтор через 1 секунд (попытка 4).
2025-01-08 17:34:01,591 - WARNING - Получена ошибка 429 для persistent_posture, повтор через 1 секунд (попытка 3).
2025-01-08 17:34:01,641 - ERROR - Не удалось получить данные для sevagoth_prime_chassis_blueprint после 5 попыток. Превышено количество попыток.
2025-01-08 17:34:01,641 - WARNING - Получены пустые данные для предмета.
2025-01-08 17:34:01,663 - WARNING - Получена ошибка 429 для nautilus_prime_cerebrum, повтор через 1 секунд (попытка 4).
2025-01-08 17:34:01,666 - INFO - Успешно получены данные для предмета: assassin_posture
2025-01-08 17:34:01,666 - ERROR - Ошибка при обработке результата: 'url_name'
Traceback (most recent call last):
  File "C:\Users\New\Documents\GitHub\WarframeMarketAnalysys\WarframeMarketDataCollector.py", line 114, in main
    all_items_data[item_data['url_name']] = item_data
                   ~~~~~~~~~^^^^^^^^^^^^
KeyError: 'url_name'
2025-01-08 17:34:01,682 - WARNING - Получена ошибка 429 для unseen_dread, повтор через 1 секунд (попытка 4).
2025-01-08 17:34:01,683 - INFO - Успешно получены данные для предмета: nautilus_prime_systems
2025-01-08 17:34:01,683 - ERROR - Ошибка при обработке результата: 'url_name'
Traceback (most recent call last):
  File "C:\Users\New\Documents\GitHub\WarframeMarketAnalysys\WarframeMarketDataCollector.py", line 114, in main
    all_items_data[item_data['url_name']] = item_data
                   ~~~~~~~~~^^^^^^^^^^^^
KeyError: 'url_name'
2025-01-08 17:34:01,713 - WARNING - Получена ошибка 429 для brute_conditioning, повтор через 1 секунд (попытка 2).
2025-01-08 17:34:01,723 - WARNING - Получена ошибка 429 для cull_the_weak, повтор через 1 секунд (попытка 2).
2025-01-08 17:34:01,730 - WARNING - Получена ошибка 429 для protector_posture, повтор через 1 секунд (попытка 3).
2025-01-08 17:34:01,731 - ERROR - Не удалось получить данные для axi_s16_relic после 5 попыток. Превышено количество попыток.
2025-01-08 17:34:01,731 - WARNING - Получены пустые данные для предмета.
2025-01-08 17:34:01,732 - WARNING - Получена ошибка 429 для neo_g7_relic, повтор через 1 секунд (попытка 5).
2025-01-08 17:34:01,744 - WARNING - Получена ошибка 429 для xaku_prime_chassis_blueprint, повтор через 1 секунд (попытка 1).
2025-01-08 17:34:01,747 - WARNING - Получена ошибка 429 для galvanized_steel, повтор через 1 секунд (попытка 2).
2025-01-08 17:34:01,750 - WARNING - Получена ошибка 429 для lith_c12_relic, повтор через 1 секунд (попытка 4).
2025-01-08 17:34:01,784 - WARNING - Получена ошибка 429 для xaku_prime_neuroptics_blueprint, повтор через 1 секунд (попытка 1).
2025-01-08 17:34:01,787 - WARNING - Получена ошибка 429 для prey_of_dynar, повтор через 1 секунд (попытка 4).
2025-01-08 17:34:01,787 - WARNING - Получена ошибка 429 для galvanized_reflex, повтор через 1 секунд (попытка 2).
2025-01-08 17:34:01,794 - WARNING - Получена ошибка 429 для trumna_prime_set, повтор через 1 секунд (попытка 1).
2025-01-08 17:34:01,848 - WARNING - Получена ошибка 429 для burning_hate, повтор через 1 секунд (попытка 4).
2025-01-08 17:34:01,889 - WARNING - Получена ошибка 429 для xaku_prime_systems_blueprint, повтор через 1 секунд (попытка 1).
2025-01-08 17:34:01,893 - INFO - Успешно получены данные для предмета: aegis_gale
2025-01-08 17:34:01,894 - ERROR - Ошибка при обработке результата: 'url_name'
Traceback (most recent call last):
  File "C:\Users\New\Documents\GitHub\WarframeMarketAnalysys\WarframeMarketDataCollector.py", line 114, in main
    all_items_data[item_data['url_name']] = item_data
                   ~~~~~~~~~^^^^^^^^^^^^
KeyError: 'url_name'
2025-01-08 17:34:01,920 - WARNING - Получена ошибка 429 для balanced_posture, повтор через 1 секунд (попытка 3).
2025-01-08 17:34:01,923 - WARNING - Получена ошибка 429 для trumna_prime_blueprint, повтор через 1 секунд (попытка 1).
2025-01-08 17:34:01,998 - WARNING - Получена ошибка 429 для resourceful_retriever, повтор через 1 секунд (попытка 3).
2025-01-08 17:34:02,000 - WARNING - Получена ошибка 429 для lith_d6_relic, повтор через 1 секунд (попытка 2).
2025-01-08 17:34:02,050 - WARNING - Получена ошибка 429 для meso_h8_relic, повтор через 1 секунд (попытка 2).
2025-01-08 17:34:02,060 - WARNING - Получена ошибка 429 для neo_k8_relic, повтор через 1 секунд (попытка 2).
2025-01-08 17:34:02,064 - WARNING - Получена ошибка 429 для lith_n15_relic, повтор через 1 секунд (попытка 5).
2025-01-08 17:34:02,064 - ERROR - Не удалось получить данные для neo_z11_relic после 5 попыток. Превышено количество попыток.
2025-01-08 17:34:02,065 - WARNING - Получены пустые данные для предмета.
2025-01-08 17:34:02,071 - WARNING - Получена ошибка 429 для neo_c5_relic, повтор через 1 секунд (попытка 2).
2025-01-08 17:34:02,078 - WARNING - Получена ошибка 429 для gastro, повтор через 1 секунд (попытка 4).
2025-01-08 17:34:02,085 - WARNING - Получена ошибка 429 для trumna_prime_barrel, повтор через 1 секунд (попытка 1).
2025-01-08 17:34:02,146 - WARNING - Получена ошибка 429 для lith_g12_relic, повтор через 1 секунд (попытка 5).
2025-01-08 17:34:02,181 - WARNING - Получена ошибка 429 для higasa_serration, повтор через 1 секунд (попытка 4).
2025-01-08 17:34:02,193 - ERROR - Не удалось получить данные для neo_p7_relic после 5 попыток. Превышено количество попыток.
2025-01-08 17:34:02,194 - WARNING - Получены пустые данные для предмета.
2025-01-08 17:34:02,254 - WARNING - Получена ошибка 429 для axi_g13_relic, повтор через 1 секунд (попытка 2).
2025-01-08 17:34:02,257 - WARNING - Получена ошибка 429 для prosperous_retriever, повтор через 1 секунд (попытка 3).
2025-01-08 17:34:02,289 - WARNING - Получена ошибка 429 для trumna_prime_stock, повтор через 1 секунд (попытка 1).
2025-01-08 17:34:02,302 - INFO - Успешно получены данные для предмета: trumna_prime_receiver
2025-01-08 17:34:02,302 - ERROR - Ошибка при обработке результата: 'url_name'
Traceback (most recent call last):
  File "C:\Users\New\Documents\GitHub\WarframeMarketAnalysys\WarframeMarketDataCollector.py", line 114, in main
    all_items_data[item_data['url_name']] = item_data
                   ~~~~~~~~~^^^^^^^^^^^^
KeyError: 'url_name'
2025-01-08 17:34:02,326 - WARNING - Получена ошибка 429 для sepsis_claws, повтор через 1 секунд (попытка 4).
2025-01-08 17:34:02,341 - WARNING - Получена ошибка 429 для epitaph_prime_set, повтор через 1 секунд (попытка 5).
2025-01-08 17:34:02,383 - WARNING - Получена ошибка 429 для quassus_prime_set, повтор через 1 секунд (попытка 1).
2025-01-08 17:34:02,399 - WARNING - Получена ошибка 429 для immunity_resistance, повтор через 1 секунд (попытка 3).
2025-01-08 17:34:02,407 - WARNING - Получена ошибка 429 для amanata_pressure, повтор через 1 секунд (попытка 4).
2025-01-08 17:34:02,468 - ERROR - Не удалось получить данные для neo_e4_relic после 5 попыток. Превышено количество попыток.
2025-01-08 17:34:02,468 - ERROR - Не удалось получить данные для meso_f5_relic после 5 попыток. Превышено количество попыток.
2025-01-08 17:34:02,469 - WARNING - Получены пустые данные для предмета.
2025-01-08 17:34:02,469 - WARNING - Получены пустые данные для предмета.
2025-01-08 17:34:02,471 - WARNING - Получена ошибка 429 для nautilus_prime_set, повтор через 1 секунд (попытка 5).
2025-01-08 17:34:02,498 - WARNING - Получена ошибка 429 для disabling_conditioning, повтор через 1 секунд (попытка 3).
2025-01-08 17:34:02,545 - WARNING - Получена ошибка 429 для bloodthirst, повтор через 1 секунд (попытка 3).
2025-01-08 17:34:02,575 - WARNING - Получена ошибка 429 для quassus_prime_handle, повтор через 1 секунд (попытка 1).
2025-01-08 17:34:02,598 - INFO - Успешно получены данные для предмета: precision_conditioning
2025-01-08 17:34:02,598 - ERROR - Ошибка при обработке результата: 'url_name'
Traceback (most recent call last):
  File "C:\Users\New\Documents\GitHub\WarframeMarketAnalysys\WarframeMarketDataCollector.py", line 114, in main
    all_items_data[item_data['url_name']] = item_data
                   ~~~~~~~~~^^^^^^^^^^^^
KeyError: 'url_name'
2025-01-08 17:34:02,599 - WARNING - Получена ошибка 429 для quassus_prime_blueprint, повтор через 1 секунд (попытка 1).
2025-01-08 17:34:02,608 - WARNING - Получена ошибка 429 для chilling_claws, повтор через 1 секунд (попытка 4).
2025-01-08 17:34:02,644 - WARNING - Получена ошибка 429 для bell_ringer, повтор через 1 секунд (попытка 3).
2025-01-08 17:34:02,654 - WARNING - Получена ошибка 429 для nautilus_prime_carapace, повтор через 1 секунд (попытка 5).
2025-01-08 17:34:02,669 - WARNING - Получена ошибка 429 для frenzied_posture, повтор через 1 секунд (попытка 4).
2025-01-08 17:34:02,670 - WARNING - Получена ошибка 429 для epitaph_prime_receiver, повтор через 1 секунд (попытка 5).
2025-01-08 17:34:02,683 - WARNING - Получена ошибка 429 для persistent_posture, повтор через 1 секунд (попытка 4).
2025-01-08 17:34:02,696 - WARNING - Получена ошибка 429 для epitaph_prime_barrel, повтор через 1 секунд (попытка 5).
2025-01-08 17:34:02,702 - WARNING - Получена ошибка 429 для quassus_prime_blade, повтор через 1 секунд (попытка 1).
2025-01-08 17:34:02,707 - WARNING - Получена ошибка 429 для xaku_prime_set, повтор через 1 секунд (попытка 2).
2025-01-08 17:34:02,743 - ERROR - Не удалось получить данные для neo_g7_relic после 5 попыток. Превышено количество попыток.
2025-01-08 17:34:02,744 - WARNING - Получены пустые данные для предмета.
2025-01-08 17:34:02,751 - WARNING - Получена ошибка 429 для nautilus_prime_cerebrum, повтор через 1 секунд (попытка 5).
2025-01-08 17:34:02,785 - WARNING - Получена ошибка 429 для unseen_dread, повтор через 1 секунд (попытка 5).
2025-01-08 17:34:02,860 - WARNING - Получена ошибка 429 для xaku_prime_chassis_blueprint, повтор через 1 секунд (попытка 2).
2025-01-08 17:34:02,862 - WARNING - Получена ошибка 429 для galvanized_reflex, повтор через 1 секунд (попытка 3).
2025-01-08 17:34:02,864 - WARNING - Получена ошибка 429 для galvanized_steel, повтор через 1 секунд (попытка 3).
2025-01-08 17:34:02,870 - WARNING - Получена ошибка 429 для lith_c12_relic, повтор через 1 секунд (попытка 5).
2025-01-08 17:34:02,882 - WARNING - Получена ошибка 429 для trumna_prime_set, повтор через 1 секунд (попытка 2).
2025-01-08 17:34:02,885 - WARNING - Получена ошибка 429 для protector_posture, повтор через 1 секунд (попытка 4).
2025-01-08 17:34:02,892 - WARNING - Получена ошибка 429 для prey_of_dynar, повтор через 1 секунд (попытка 5).
2025-01-08 17:34:02,897 - WARNING - Получена ошибка 429 для xaku_prime_neuroptics_blueprint, повтор через 1 секунд (попытка 2).
2025-01-08 17:34:02,936 - WARNING - Получена ошибка 429 для xaku_prime_blueprint, повтор через 1 секунд (попытка 2).
2025-01-08 17:34:02,950 - WARNING - Получена ошибка 429 для burning_hate, повтор через 1 секунд (попытка 5).
2025-01-08 17:34:02,984 - WARNING - Получена ошибка 429 для xaku_prime_systems_blueprint, повтор через 1 секунд (попытка 2).
2025-01-08 17:34:03,028 - WARNING - Получена ошибка 429 для balanced_posture, повтор через 1 секунд (попытка 4).
2025-01-08 17:34:03,039 - WARNING - Получена ошибка 429 для trumna_prime_blueprint, повтор через 1 секунд (попытка 2).
2025-01-08 17:34:03,068 - ERROR - Не удалось получить данные для lith_n15_relic после 5 попыток. Превышено количество попыток.
2025-01-08 17:34:03,068 - WARNING - Получены пустые данные для предмета.
2025-01-08 17:34:03,111 - WARNING - Получена ошибка 429 для lith_d6_relic, повтор через 1 секунд (попытка 3).
2025-01-08 17:34:03,145 - WARNING - Получена ошибка 429 для brute_conditioning, повтор через 1 секунд (попытка 3).
2025-01-08 17:34:03,160 - ERROR - Не удалось получить данные для lith_g12_relic после 5 попыток. Превышено количество попыток.
2025-01-08 17:34:03,161 - WARNING - Получены пустые данные для предмета.
2025-01-08 17:34:03,161 - WARNING - Получена ошибка 429 для meso_h8_relic, повтор через 1 секунд (попытка 3).
2025-01-08 17:34:03,172 - WARNING - Получена ошибка 429 для axi_a19_relic, повтор через 1 секунд (попытка 1).
2025-01-08 17:34:03,194 - WARNING - Получена ошибка 429 для resourceful_retriever, повтор через 1 секунд (попытка 4).
2025-01-08 17:34:03,207 - WARNING - Получена ошибка 429 для neo_c5_relic, повтор через 1 секунд (попытка 3).
2025-01-08 17:34:03,207 - WARNING - Получена ошибка 429 для trumna_prime_barrel, повтор через 1 секунд (попытка 2).
2025-01-08 17:34:03,209 - WARNING - Получена ошибка 429 для axi_g14_relic, повтор через 1 секунд (попытка 1).
2025-01-08 17:34:03,234 - WARNING - Получена ошибка 429 для gastro, повтор через 1 секунд (попытка 5).
2025-01-08 17:34:03,267 - WARNING - Получена ошибка 429 для axi_h8_relic, повтор через 1 секунд (попытка 1).
2025-01-08 17:34:03,270 - INFO - Успешно получены данные для предмета: cull_the_weak
2025-01-08 17:34:03,271 - ERROR - Ошибка при обработке результата: 'url_name'
Traceback (most recent call last):
  File "C:\Users\New\Documents\GitHub\WarframeMarketAnalysys\WarframeMarketDataCollector.py", line 114, in main
    all_items_data[item_data['url_name']] = item_data
                   ~~~~~~~~~^^^^^^^^^^^^
KeyError: 'url_name'
2025-01-08 17:34:03,298 - WARNING - Получена ошибка 429 для higasa_serration, повтор через 1 секунд (попытка 5).
2025-01-08 17:34:03,328 - INFO - Успешно получены данные для предмета: neo_k8_relic
2025-01-08 17:34:03,328 - ERROR - Ошибка при обработке результата: 'url_name'
Traceback (most recent call last):
  File "C:\Users\New\Documents\GitHub\WarframeMarketAnalysys\WarframeMarketDataCollector.py", line 114, in main
    all_items_data[item_data['url_name']] = item_data
                   ~~~~~~~~~^^^^^^^^^^^^
KeyError: 'url_name'
2025-01-08 17:34:03,344 - ERROR - Не удалось получить данные для epitaph_prime_set после 5 попыток. Превышено количество попыток.
2025-01-08 17:34:03,344 - WARNING - Получены пустые данные для предмета.
2025-01-08 17:34:03,357 - WARNING - Получена ошибка 429 для axi_g13_relic, повтор через 1 секунд (попытка 3).
2025-01-08 17:34:03,379 - WARNING - Получена ошибка 429 для axi_t12_relic, повтор через 1 секунд (попытка 1).
2025-01-08 17:34:03,379 - WARNING - Получена ошибка 429 для prosperous_retriever, повтор через 1 секунд (попытка 4).
2025-01-08 17:34:03,404 - WARNING - Получена ошибка 429 для trumna_prime_stock, повтор через 1 секунд (попытка 2).
2025-01-08 17:34:03,409 - WARNING - Получена ошибка 429 для sepsis_claws, повтор через 1 секунд (попытка 5).
2025-01-08 17:34:03,464 - WARNING - Получена ошибка 429 для neo_g8_relic, повтор через 1 секунд (попытка 1).
2025-01-08 17:34:03,482 - ERROR - Не удалось получить данные для nautilus_prime_set после 5 попыток. Превышено количество попыток.
2025-01-08 17:34:03,482 - WARNING - Получены пустые данные для предмета.
2025-01-08 17:34:03,514 - WARNING - Получена ошибка 429 для quassus_prime_set, повтор через 1 секунд (попытка 2).
2025-01-08 17:34:03,517 - WARNING - Получена ошибка 429 для amanata_pressure, повтор через 1 секунд (попытка 5).
2025-01-08 17:34:03,560 - WARNING - Получена ошибка 429 для neo_w2_relic, повтор через 1 секунд (попытка 1).
2025-01-08 17:34:03,664 - ERROR - Не удалось получить данные для nautilus_prime_carapace после 5 попыток. Превышено количество попыток.
2025-01-08 17:34:03,664 - WARNING - Получены пустые данные для предмета.
2025-01-08 17:34:03,679 - ERROR - Не удалось получить данные для epitaph_prime_receiver после 5 попыток. Превышено количество попыток.
2025-01-08 17:34:03,680 - WARNING - Получены пустые данные для предмета.
2025-01-08 17:34:03,692 - WARNING - Получена ошибка 429 для bloodthirst, повтор через 1 секунд (попытка 4).
2025-01-08 17:34:03,696 - WARNING - Получена ошибка 429 для quassus_prime_handle, повтор через 1 секунд (попытка 2).
2025-01-08 17:34:03,697 - ERROR - Не удалось получить данные для epitaph_prime_barrel после 5 попыток. Превышено количество попыток.
2025-01-08 17:34:03,697 - WARNING - Получены пустые данные для предмета.
2025-01-08 17:34:03,704 - WARNING - Получена ошибка 429 для quassus_prime_blueprint, повтор через 1 секунд (попытка 2).
2025-01-08 17:34:03,714 - WARNING - Получена ошибка 429 для chilling_claws, повтор через 1 секунд (попытка 5).
2025-01-08 17:34:03,740 - WARNING - Получена ошибка 429 для neo_l4_relic, повтор через 1 секунд (попытка 1).
2025-01-08 17:34:03,746 - WARNING - Получена ошибка 429 для bell_ringer, повтор через 1 секунд (попытка 4).
2025-01-08 17:34:03,756 - ERROR - Не удалось получить данные для nautilus_prime_cerebrum после 5 попыток. Превышено количество попыток.
2025-01-08 17:34:03,757 - WARNING - Получены пустые данные для предмета.
2025-01-08 17:34:03,764 - INFO - Успешно получены данные для предмета: neo_q1_relic
2025-01-08 17:34:03,764 - ERROR - Ошибка при обработке результата: 'url_name'
Traceback (most recent call last):
  File "C:\Users\New\Documents\GitHub\WarframeMarketAnalysys\WarframeMarketDataCollector.py", line 114, in main
    all_items_data[item_data['url_name']] = item_data
                   ~~~~~~~~~^^^^^^^^^^^^
KeyError: 'url_name'
2025-01-08 17:34:03,776 - WARNING - Получена ошибка 429 для frenzied_posture, повтор через 1 секунд (попытка 5).
2025-01-08 17:34:03,787 - ERROR - Не удалось получить данные для unseen_dread после 5 попыток. Превышено количество попыток.
2025-01-08 17:34:03,788 - WARNING - Получены пустые данные для предмета.
2025-01-08 17:34:03,797 - WARNING - Получена ошибка 429 для persistent_posture, повтор через 1 секунд (попытка 5).
2025-01-08 17:34:03,804 - WARNING - Получена ошибка 429 для quassus_prime_blade, повтор через 1 секунд (попытка 2).
2025-01-08 17:34:03,837 - WARNING - Получена ошибка 429 для xaku_prime_set, повтор через 1 секунд (попытка 3).
2025-01-08 17:34:03,880 - ERROR - Не удалось получить данные для lith_c12_relic после 5 попыток. Превышено количество попыток.
2025-01-08 17:34:03,880 - WARNING - Получены пустые данные для предмета.
2025-01-08 17:34:03,895 - ERROR - Не удалось получить данные для prey_of_dynar после 5 попыток. Превышено количество попыток.
2025-01-08 17:34:03,895 - WARNING - Получены пустые данные для предмета.
2025-01-08 17:34:03,942 - WARNING - Получена ошибка 429 для galvanized_reflex, повтор через 1 секунд (попытка 4).
2025-01-08 17:34:03,956 - ERROR - Не удалось получить данные для burning_hate после 5 попыток. Превышено количество попыток.
2025-01-08 17:34:03,956 - WARNING - Получены пустые данные для предмета.
2025-01-08 17:34:03,963 - WARNING - Получена ошибка 429 для xaku_prime_chassis_blueprint, повтор через 1 секунд (попытка 3).
2025-01-08 17:34:03,984 - WARNING - Получена ошибка 429 для lith_m9_relic, повтор через 1 секунд (попытка 1).
2025-01-08 17:34:03,988 - INFO - Успешно получены данные для предмета: immunity_resistance
2025-01-08 17:34:03,988 - ERROR - Ошибка при обработке результата: 'url_name'
Traceback (most recent call last):
  File "C:\Users\New\Documents\GitHub\WarframeMarketAnalysys\WarframeMarketDataCollector.py", line 114, in main
    all_items_data[item_data['url_name']] = item_data
                   ~~~~~~~~~^^^^^^^^^^^^
KeyError: 'url_name'
2025-01-08 17:34:03,994 - WARNING - Получена ошибка 429 для lith_g13_relic, повтор через 1 секунд (попытка 1).
2025-01-08 17:34:03,995 - WARNING - Получена ошибка 429 для galvanized_steel, повтор через 1 секунд (попытка 4).
2025-01-08 17:34:04,002 - WARNING - Получена ошибка 429 для lith_n16_relic, повтор через 1 секунд (попытка 1).
2025-01-08 17:34:04,006 - WARNING - Получена ошибка 429 для trumna_prime_set, повтор через 1 секунд (попытка 3).
2025-01-08 17:34:04,074 - INFO - Успешно получены данные для предмета: disabling_conditioning
2025-01-08 17:34:04,074 - ERROR - Ошибка при обработке результата: 'url_name'
Traceback (most recent call last):
  File "C:\Users\New\Documents\GitHub\WarframeMarketAnalysys\WarframeMarketDataCollector.py", line 114, in main
    all_items_data[item_data['url_name']] = item_data
                   ~~~~~~~~~^^^^^^^^^^^^
KeyError: 'url_name'
2025-01-08 17:34:04,075 - WARNING - Получена ошибка 429 для meso_e6_relic, повтор через 1 секунд (попытка 1).
2025-01-08 17:34:04,103 - INFO - Успешно получены данные для предмета: xaku_prime_neuroptics_blueprint
2025-01-08 17:34:04,104 - ERROR - Ошибка при обработке результата: 'url_name'
Traceback (most recent call last):
  File "C:\Users\New\Documents\GitHub\WarframeMarketAnalysys\WarframeMarketDataCollector.py", line 114, in main
    all_items_data[item_data['url_name']] = item_data
                   ~~~~~~~~~^^^^^^^^^^^^
KeyError: 'url_name'
2025-01-08 17:34:04,107 - INFO - Успешно получены данные для предмета: meso_v10_relic
2025-01-08 17:34:04,107 - ERROR - Ошибка при обработке результата: 'url_name'
Traceback (most recent call last):
  File "C:\Users\New\Documents\GitHub\WarframeMarketAnalysys\WarframeMarketDataCollector.py", line 114, in main
    all_items_data[item_data['url_name']] = item_data
                   ~~~~~~~~~^^^^^^^^^^^^
KeyError: 'url_name'
2025-01-08 17:34:04,147 - WARNING - Получена ошибка 429 для balanced_posture, повтор через 1 секунд (попытка 5).
2025-01-08 17:34:04,149 - WARNING - Получена ошибка 429 для xaku_prime_systems_blueprint, повтор через 1 секунд (попытка 3).
2025-01-08 17:34:04,196 - WARNING - Получена ошибка 429 для arcane_impetus, повтор через 1 секунд (попытка 1).
2025-01-08 17:34:04,218 - WARNING - Получена ошибка 429 для secondary_enervate, повтор через 1 секунд (попытка 1).
2025-01-08 17:34:04,246 - ERROR - Не удалось получить данные для gastro после 5 попыток. Превышено количество попыток.
2025-01-08 17:34:04,247 - WARNING - Получены пустые данные для предмета.
2025-01-08 17:34:04,261 - WARNING - Получена ошибка 429 для brute_conditioning, повтор через 1 секунд (попытка 4).
2025-01-08 17:34:04,264 - WARNING - Получена ошибка 429 для lith_x1_relic, повтор через 1 секунд (попытка 1).
2025-01-08 17:34:04,286 - WARNING - Получена ошибка 429 для protector_posture, повтор через 1 секунд (попытка 5).
2025-01-08 17:34:04,308 - INFO - Успешно получены данные для предмета: meso_g8_relic
2025-01-08 17:34:04,308 - ERROR - Не удалось получить данные для higasa_serration после 5 попыток. Превышено количество попыток.
2025-01-08 17:34:04,308 - ERROR - Ошибка при обработке результата: 'url_name'
Traceback (most recent call last):
  File "C:\Users\New\Documents\GitHub\WarframeMarketAnalysys\WarframeMarketDataCollector.py", line 114, in main
    all_items_data[item_data['url_name']] = item_data
                   ~~~~~~~~~^^^^^^^^^^^^
KeyError: 'url_name'
2025-01-08 17:34:04,309 - WARNING - Получены пустые данные для предмета.
2025-01-08 17:34:04,313 - WARNING - Получена ошибка 429 для trumna_prime_barrel, повтор через 1 секунд (попытка 3).
2025-01-08 17:34:04,317 - WARNING - Получена ошибка 429 для primary_crux, повтор через 1 секунд (попытка 1).
2025-01-08 17:34:04,319 - WARNING - Получена ошибка 429 для axi_g14_relic, повтор через 1 секунд (попытка 2).
2025-01-08 17:34:04,320 - WARNING - Получена ошибка 429 для meso_h8_relic, повтор через 1 секунд (попытка 4).
2025-01-08 17:34:04,323 - WARNING - Получена ошибка 429 для lith_d6_relic, повтор через 1 секунд (попытка 4).
2025-01-08 17:34:04,324 - WARNING - Получена ошибка 429 для axi_a19_relic, повтор через 1 секунд (попытка 2).
2025-01-08 17:34:04,325 - WARNING - Получена ошибка 429 для resourceful_retriever, повтор через 1 секунд (попытка 5).
2025-01-08 17:34:04,338 - INFO - Успешно получены данные для предмета: xaku_prime_blueprint
2025-01-08 17:34:04,339 - ERROR - Ошибка при обработке результата: 'url_name'
Traceback (most recent call last):
  File "C:\Users\New\Documents\GitHub\WarframeMarketAnalysys\WarframeMarketDataCollector.py", line 114, in main
    all_items_data[item_data['url_name']] = item_data
                   ~~~~~~~~~^^^^^^^^^^^^
KeyError: 'url_name'
2025-01-08 17:34:04,345 - WARNING - Получена ошибка 429 для neo_c5_relic, повтор через 1 секунд (попытка 4).
2025-01-08 17:34:04,387 - WARNING - Получена ошибка 429 для arcane_camisado, повтор через 1 секунд (попытка 1).
2025-01-08 17:34:04,400 - WARNING - Получена ошибка 429 для melee_doughty, повтор через 1 секунд (попытка 1).
2025-01-08 17:34:04,411 - WARNING - Получена ошибка 429 для arcane_crepuscular, повтор через 1 секунд (попытка 1).
2025-01-08 17:34:04,411 - ERROR - Не удалось получить данные для sepsis_claws после 5 попыток. Превышено количество попыток.
2025-01-08 17:34:04,412 - WARNING - Получены пустые данные для предмета.
2025-01-08 17:34:04,413 - WARNING - Получена ошибка 429 для axi_h8_relic, повтор через 1 секунд (попытка 2).
2025-01-08 17:34:04,440 - WARNING - Получена ошибка 429 для arcane_bellicose, повтор через 1 секунд (попытка 1).
2025-01-08 17:34:04,442 - WARNING - Получена ошибка 429 для meso_t7_relic, повтор через 1 секунд (попытка 1).
2025-01-08 17:34:04,447 - WARNING - Получена ошибка 429 для arcane_truculence, повтор через 1 секунд (попытка 1).
2025-01-08 17:34:04,499 - WARNING - Получена ошибка 429 для prosperous_retriever, повтор через 1 секунд (попытка 5).
2025-01-08 17:34:04,514 - WARNING - Получена ошибка 429 для trumna_prime_stock, повтор через 1 секунд (попытка 3).
2025-01-08 17:34:04,523 - ERROR - Не удалось получить данные для amanata_pressure после 5 попыток. Превышено количество попыток.
2025-01-08 17:34:04,523 - WARNING - Получены пустые данные для предмета.
2025-01-08 17:34:04,524 - WARNING - Получена ошибка 429 для mall_rotunda_simulacrum, повтор через 1 секунд (попытка 1).
2025-01-08 17:34:04,559 - WARNING - Получена ошибка 429 для axi_t12_relic, повтор через 1 секунд (попытка 2).
2025-01-08 17:34:04,617 - WARNING - Получена ошибка 429 для neo_g8_relic, повтор через 1 секунд (попытка 2).
2025-01-08 17:34:04,623 - WARNING - Получена ошибка 429 для quassus_prime_set, повтор через 1 секунд (попытка 3).
2025-01-08 17:34:04,636 - WARNING - Получена ошибка 429 для höllvanian_courtyard_simulacrum, повтор через 1 секунд (попытка 1).
2025-01-08 17:34:04,678 - WARNING - Получена ошибка 429 для neo_w2_relic, повтор через 1 секунд (попытка 2).
2025-01-08 17:34:04,720 - ERROR - Не удалось получить данные для chilling_claws после 5 попыток. Превышено количество попыток.
2025-01-08 17:34:04,720 - WARNING - Получены пустые данные для предмета.
2025-01-08 17:34:04,734 - INFO - Успешно получены данные для предмета: axi_g13_relic
2025-01-08 17:34:04,735 - ERROR - Ошибка при обработке результата: 'url_name'
Traceback (most recent call last):
  File "C:\Users\New\Documents\GitHub\WarframeMarketAnalysys\WarframeMarketDataCollector.py", line 114, in main
    all_items_data[item_data['url_name']] = item_data
                   ~~~~~~~~~^^^^^^^^^^^^
KeyError: 'url_name'
2025-01-08 17:34:04,780 - ERROR - Не удалось получить данные для frenzied_posture после 5 попыток. Превышено количество попыток.
2025-01-08 17:34:04,781 - WARNING - Получены пустые данные для предмета.
2025-01-08 17:34:04,783 - WARNING - Получена ошибка 429 для quassus_prime_blueprint, повтор через 1 секунд (попытка 3).
2025-01-08 17:34:04,800 - WARNING - Получена ошибка 429 для bloodthirst, повтор через 1 секунд (попытка 5).
2025-01-08 17:34:04,800 - ERROR - Не удалось получить данные для persistent_posture после 5 попыток. Превышено количество попыток.
2025-01-08 17:34:04,800 - WARNING - Получены пустые данные для предмета.
2025-01-08 17:34:04,815 - WARNING - Получена ошибка 429 для tech_titan_electronics_store, повтор через 1 секунд (попытка 1).
2025-01-08 17:34:04,818 - WARNING - Получена ошибка 429 для quassus_prime_handle, повтор через 1 секунд (попытка 3).
2025-01-08 17:34:04,847 - WARNING - Получена ошибка 429 для neo_l4_relic, повтор через 1 секунд (попытка 2).
2025-01-08 17:34:04,857 - WARNING - Получена ошибка 429 для bell_ringer, повтор через 1 секунд (попытка 5).
2025-01-08 17:34:04,868 - WARNING - Получена ошибка 429 для trumna_prime_blueprint, повтор через 1 секунд (попытка 3).
2025-01-08 17:34:04,870 - WARNING - Получена ошибка 429 для höllvanian_intersection_in_winter, повтор через 1 секунд (попытка 1).
2025-01-08 17:34:04,903 - WARNING - Получена ошибка 429 для höllvania_central_mall_subway, повтор через 1 секунд (попытка 1).
2025-01-08 17:34:04,938 - WARNING - Получена ошибка 429 для quassus_prime_blade, повтор через 1 секунд (попытка 3).
2025-01-08 17:34:04,979 - WARNING - Получена ошибка 429 для xaku_prime_set, повтор через 1 секунд (попытка 4).
2025-01-08 17:34:04,983 - INFO - Успешно получены данные для предмета: höllvanian_terrace_in_summer
2025-01-08 17:34:04,983 - ERROR - Ошибка при обработке результата: 'url_name'
Traceback (most recent call last):
  File "C:\Users\New\Documents\GitHub\WarframeMarketAnalysys\WarframeMarketDataCollector.py", line 114, in main
    all_items_data[item_data['url_name']] = item_data
                   ~~~~~~~~~^^^^^^^^^^^^
KeyError: 'url_name'
2025-01-08 17:34:05,064 - WARNING - Получена ошибка 429 для galvanized_reflex, повтор через 1 секунд (попытка 5).
2025-01-08 17:34:05,090 - WARNING - Получена ошибка 429 для lith_m9_relic, повтор через 1 секунд (попытка 2).
2025-01-08 17:34:05,100 - WARNING - Получена ошибка 429 для lith_g13_relic, повтор через 1 секунд (попытка 2).
2025-01-08 17:34:05,101 - WARNING - Получена ошибка 429 для xaku_prime_chassis_blueprint, повтор через 1 секунд (попытка 4).
2025-01-08 17:34:05,110 - WARNING - Получена ошибка 429 для galvanized_steel, повтор через 1 секунд (попытка 5).
2025-01-08 17:34:05,116 - WARNING - Получена ошибка 429 для lith_n16_relic, повтор через 1 секунд (попытка 2).
2025-01-08 17:34:05,144 - WARNING - Получена ошибка 429 для höllvanian_tenements_in_summer, повтор через 1 секунд (попытка 1).
2025-01-08 17:34:05,151 - ERROR - Не удалось получить данные для balanced_posture после 5 попыток. Превышено количество попыток.
2025-01-08 17:34:05,152 - WARNING - Получены пустые данные для предмета.
2025-01-08 17:34:05,152 - WARNING - Получена ошибка 429 для trumna_prime_set, повтор через 1 секунд (попытка 4).
2025-01-08 17:34:05,213 - INFO - Успешно получены данные для предмета: meso_e6_relic
2025-01-08 17:34:05,214 - ERROR - Ошибка при обработке результата: 'url_name'
Traceback (most recent call last):
  File "C:\Users\New\Documents\GitHub\WarframeMarketAnalysys\WarframeMarketDataCollector.py", line 114, in main
    all_items_data[item_data['url_name']] = item_data
                   ~~~~~~~~~^^^^^^^^^^^^
KeyError: 'url_name'
2025-01-08 17:34:05,260 - WARNING - Получена ошибка 429 для xaku_prime_systems_blueprint, повтор через 1 секунд (попытка 4).
2025-01-08 17:34:05,261 - WARNING - Получена ошибка 429 для höllvanian_historic_quarter_in_spring, повтор через 1 секунд (попытка 1).
2025-01-08 17:34:05,289 - ERROR - Не удалось получить данные для protector_posture после 5 попыток. Превышено количество попыток.
2025-01-08 17:34:05,289 - WARNING - Получены пустые данные для предмета.
2025-01-08 17:34:05,296 - WARNING - Получена ошибка 429 для höllvanian_old_town_in_fall, повтор через 1 секунд (попытка 1).
2025-01-08 17:34:05,321 - WARNING - Получена ошибка 429 для secondary_enervate, повтор через 1 секунд (попытка 2).
2025-01-08 17:34:05,335 - ERROR - Не удалось получить данные для resourceful_retriever после 5 попыток. Превышено количество попыток.
2025-01-08 17:34:05,335 - WARNING - Получены пустые данные для предмета.
2025-01-08 17:34:05,372 - WARNING - Получена ошибка 429 для brute_conditioning, повтор через 1 секунд (попытка 5).
2025-01-08 17:34:05,381 - WARNING - Получена ошибка 429 для lith_x1_relic, повтор через 1 секунд (попытка 2).
2025-01-08 17:34:05,408 - WARNING - Получена ошибка 429 для orbit_arcade, повтор через 1 секунд (попытка 1).
2025-01-08 17:34:05,414 - WARNING - Получена ошибка 429 для axi_a19_relic, повтор через 1 секунд (попытка 3).
2025-01-08 17:34:05,418 - WARNING - Получена ошибка 429 для primary_crux, повтор через 1 секунд (попытка 2).
2025-01-08 17:34:05,443 - WARNING - Получена ошибка 429 для lith_d6_relic, повтор через 1 секунд (попытка 5).
2025-01-08 17:34:05,446 - WARNING - Получена ошибка 429 для central_mall_backroom, повтор через 1 секунд (попытка 1).
2025-01-08 17:34:05,457 - WARNING - Получена ошибка 429 для trumna_prime_barrel, повтор через 1 секунд (попытка 4).
2025-01-08 17:34:05,460 - WARNING - Получена ошибка 429 для axi_g14_relic, повтор через 1 секунд (попытка 3).
2025-01-08 17:34:05,471 - WARNING - Получена ошибка 429 для meso_h8_relic, повтор через 1 секунд (попытка 5).
2025-01-08 17:34:05,502 - ERROR - Не удалось получить данные для prosperous_retriever после 5 попыток. Превышено количество попыток.
2025-01-08 17:34:05,502 - WARNING - Получены пустые данные для предмета.
2025-01-08 17:34:05,511 - WARNING - Получена ошибка 429 для arcane_camisado, повтор через 1 секунд (попытка 2).
2025-01-08 17:34:05,523 - WARNING - Получена ошибка 429 для arcane_bellicose, повтор через 1 секунд (попытка 2).
2025-01-08 17:34:05,523 - WARNING - Получена ошибка 429 для melee_doughty, повтор через 1 секунд (попытка 2).
2025-01-08 17:34:05,533 - INFO - Успешно получены данные для предмета: axi_h8_relic
2025-01-08 17:34:05,534 - ERROR - Ошибка при обработке результата: 'url_name'
Traceback (most recent call last):
  File "C:\Users\New\Documents\GitHub\WarframeMarketAnalysys\WarframeMarketDataCollector.py", line 114, in main
    all_items_data[item_data['url_name']] = item_data
                   ~~~~~~~~~^^^^^^^^^^^^
KeyError: 'url_name'
2025-01-08 17:34:05,551 - WARNING - Получена ошибка 429 для meso_t7_relic, повтор через 1 секунд (попытка 2).
2025-01-08 17:34:05,571 - WARNING - Получена ошибка 429 для arcane_truculence, повтор через 1 секунд (попытка 2).
2025-01-08 17:34:05,598 - WARNING - Получена ошибка 429 для trumna_prime_stock, повтор через 1 секунд (попытка 4).
2025-01-08 17:34:05,606 - WARNING - Получена ошибка 429 для arcane_impetus, повтор через 1 секунд (попытка 2).
2025-01-08 17:34:05,607 - WARNING - Получена ошибка 429 для mall_rotunda_simulacrum, повтор через 1 секунд (попытка 2).
2025-01-08 17:34:05,638 - WARNING - Получена ошибка 429 для magnetic_strafe, повтор через 1 секунд (попытка 1).
2025-01-08 17:34:05,654 - WARNING - Получена ошибка 429 для magnetic_welt, повтор через 1 секунд (попытка 1).
2025-01-08 17:34:05,675 - WARNING - Получена ошибка 429 для axi_t12_relic, повтор через 1 секунд (попытка 3).
2025-01-08 17:34:05,710 - WARNING - Получена ошибка 429 для quassus_prime_set, повтор через 1 секунд (попытка 4).
2025-01-08 17:34:05,728 - WARNING - Получена ошибка 429 для höllvanian_courtyard_simulacrum, повтор через 1 секунд (попытка 2).
2025-01-08 17:34:05,745 - WARNING - Получена ошибка 429 для neo_g8_relic, повтор через 1 секунд (попытка 3).
2025-01-08 17:34:05,760 - WARNING - Получена ошибка 429 для neo_c5_relic, повтор через 1 секунд (попытка 5).
2025-01-08 17:34:05,764 - WARNING - Получена ошибка 429 для neo_w2_relic, повтор через 1 секунд (попытка 3).
2025-01-08 17:34:05,807 - ERROR - Не удалось получить данные для bloodthirst после 5 попыток. Превышено количество попыток.
2025-01-08 17:34:05,807 - WARNING - Получены пустые данные для предмета.
2025-01-08 17:34:05,869 - ERROR - Не удалось получить данные для bell_ringer после 5 попыток. Превышено количество попыток.
2025-01-08 17:34:05,869 - WARNING - Получены пустые данные для предмета.
2025-01-08 17:34:05,886 - WARNING - Получена ошибка 429 для arcane_crepuscular, повтор через 1 секунд (попытка 2).
2025-01-08 17:34:05,908 - WARNING - Получена ошибка 429 для quassus_prime_blueprint, повтор через 1 секунд (попытка 4).
2025-01-08 17:34:05,913 - INFO - Успешно получены данные для предмета: radon_claws
2025-01-08 17:34:05,913 - ERROR - Ошибка при обработке результата: 'url_name'
Traceback (most recent call last):
  File "C:\Users\New\Documents\GitHub\WarframeMarketAnalysys\WarframeMarketDataCollector.py", line 114, in main
    all_items_data[item_data['url_name']] = item_data
                   ~~~~~~~~~^^^^^^^^^^^^
KeyError: 'url_name'
2025-01-08 17:34:05,946 - WARNING - Получена ошибка 429 для neo_l4_relic, повтор через 1 секунд (попытка 3).
2025-01-08 17:34:05,955 - WARNING - Получена ошибка 429 для tech_titan_electronics_store, повтор через 1 секунд (попытка 2).
2025-01-08 17:34:06,018 - WARNING - Получена ошибка 429 для trumna_prime_blueprint, повтор через 1 секунд (попытка 4).
2025-01-08 17:34:06,042 - WARNING - Получена ошибка 429 для magnetic_claws, повтор через 1 секунд (попытка 1).
2025-01-08 17:34:06,062 - WARNING - Получена ошибка 429 для höllvanian_intersection_in_winter, повтор через 1 секунд (попытка 2).
2025-01-08 17:34:06,071 - ERROR - Не удалось получить данные для galvanized_reflex после 5 попыток. Превышено количество попыток.
2025-01-08 17:34:06,071 - WARNING - Получены пустые данные для предмета.
2025-01-08 17:34:06,101 - WARNING - Получена ошибка 429 для primary_acuity, повтор через 1 секунд (попытка 1).
2025-01-08 17:34:06,102 - WARNING - Получена ошибка 429 для höllvania_central_mall_subway, повтор через 1 секунд (попытка 2).
2025-01-08 17:34:06,104 - WARNING - Получена ошибка 429 для xaku_prime_set, повтор через 1 секунд (попытка 5).
2025-01-08 17:34:06,109 - WARNING - Получена ошибка 429 для quassus_prime_blade, повтор через 1 секунд (попытка 4).
2025-01-08 17:34:06,117 - ERROR - Не удалось получить данные для galvanized_steel после 5 попыток. Превышено количество попыток.
2025-01-08 17:34:06,117 - WARNING - Получены пустые данные для предмета.
2025-01-08 17:34:06,219 - INFO - Успешно получены данные для предмета: xaku_prime_chassis_blueprint
2025-01-08 17:34:06,219 - ERROR - Ошибка при обработке результата: 'url_name'
Traceback (most recent call last):
  File "C:\Users\New\Documents\GitHub\WarframeMarketAnalysys\WarframeMarketDataCollector.py", line 114, in main
    all_items_data[item_data['url_name']] = item_data
                   ~~~~~~~~~^^^^^^^^^^^^
KeyError: 'url_name'
2025-01-08 17:34:06,227 - INFO - Успешно получены данные для предмета: lith_g13_relic
2025-01-08 17:34:06,227 - ERROR - Ошибка при обработке результата: 'url_name'
Traceback (most recent call last):
  File "C:\Users\New\Documents\GitHub\WarframeMarketAnalysys\WarframeMarketDataCollector.py", line 114, in main
    all_items_data[item_data['url_name']] = item_data
                   ~~~~~~~~~^^^^^^^^^^^^
KeyError: 'url_name'
2025-01-08 17:34:06,234 - WARNING - Получена ошибка 429 для quassus_prime_handle, повтор через 1 секунд (попытка 4).
2025-01-08 17:34:06,236 - WARNING - Получена ошибка 429 для magnetic_capacity, повтор через 1 секунд (попытка 1).
2025-01-08 17:34:06,259 - WARNING - Получена ошибка 429 для lith_n16_relic, повтор через 1 секунд (попытка 3).
2025-01-08 17:34:06,261 - WARNING - Получена ошибка 429 для höllvanian_tenements_in_summer, повтор через 1 секунд (попытка 2).
2025-01-08 17:34:06,269 - WARNING - Получена ошибка 429 для lith_m9_relic, повтор через 1 секунд (попытка 3).
2025-01-08 17:34:06,270 - WARNING - Получена ошибка 429 для trumna_prime_set, повтор через 1 секунд (попытка 5).
2025-01-08 17:34:06,322 - WARNING - Получена ошибка 429 для merciless_gunfight, повтор через 1 секунд (попытка 1).
2025-01-08 17:34:06,362 - WARNING - Получена ошибка 429 для xaku_prime_systems_blueprint, повтор через 1 секунд (попытка 5).
2025-01-08 17:34:06,369 - WARNING - Получена ошибка 429 для höllvanian_historic_quarter_in_spring, повтор через 1 секунд (попытка 2).
2025-01-08 17:34:06,377 - ERROR - Не удалось получить данные для brute_conditioning после 5 попыток. Превышено количество попыток.
2025-01-08 17:34:06,377 - WARNING - Получены пустые данные для предмета.
2025-01-08 17:34:06,405 - WARNING - Получена ошибка 429 для höllvanian_old_town_in_fall, повтор через 1 секунд (попытка 2).
2025-01-08 17:34:06,432 - INFO - Успешно получены данные для предмета: pistol_acuity
2025-01-08 17:34:06,432 - ERROR - Ошибка при обработке результата: 'url_name'
Traceback (most recent call last):
  File "C:\Users\New\Documents\GitHub\WarframeMarketAnalysys\WarframeMarketDataCollector.py", line 114, in main
    all_items_data[item_data['url_name']] = item_data
                   ~~~~~~~~~^^^^^^^^^^^^
KeyError: 'url_name'
2025-01-08 17:34:06,434 - WARNING - Получена ошибка 429 для secondary_enervate, повтор через 1 секунд (попытка 3).
2025-01-08 17:34:06,453 - ERROR - Не удалось получить данные для lith_d6_relic после 5 попыток. Превышено количество попыток.
2025-01-08 17:34:06,453 - WARNING - Получены пустые данные для предмета.
2025-01-08 17:34:06,478 - WARNING - Получена ошибка 429 для magnetic_rush, повтор через 1 секунд (попытка 1).
2025-01-08 17:34:06,478 - ERROR - Не удалось получить данные для meso_h8_relic после 5 попыток. Превышено количество попыток.
2025-01-08 17:34:06,479 - WARNING - Получены пустые данные для предмета.
2025-01-08 17:34:06,500 - WARNING - Получена ошибка 429 для lith_x1_relic, повтор через 1 секунд (попытка 3).
2025-01-08 17:34:06,526 - WARNING - Получена ошибка 429 для worthy_comradery, повтор через 1 секунд (попытка 1).
2025-01-08 17:34:06,527 - WARNING - Получена ошибка 429 для orbit_arcade, повтор через 1 секунд (попытка 2).
2025-01-08 17:34:06,528 - WARNING - Получена ошибка 429 для axi_a19_relic, повтор через 1 секунд (попытка 4).
2025-01-08 17:34:06,532 - WARNING - Получена ошибка 429 для summoner’s_wrath, повтор через 1 секунд (попытка 1).
2025-01-08 17:34:06,545 - WARNING - Получена ошибка 429 для central_mall_backroom, повтор через 1 секунд (попытка 2).
2025-01-08 17:34:06,545 - INFO - Успешно получены данные для предмета: primary_crux
2025-01-08 17:34:06,545 - ERROR - Ошибка при обработке результата: 'url_name'
Traceback (most recent call last):
  File "C:\Users\New\Documents\GitHub\WarframeMarketAnalysys\WarframeMarketDataCollector.py", line 114, in main
    all_items_data[item_data['url_name']] = item_data
                   ~~~~~~~~~^^^^^^^^^^^^
KeyError: 'url_name'
2025-01-08 17:34:06,571 - WARNING - Получена ошибка 429 для trumna_prime_barrel, повтор через 1 секунд (попытка 5).
2025-01-08 17:34:06,574 - WARNING - Получена ошибка 429 для axi_g14_relic, повтор через 1 секунд (попытка 4).
2025-01-08 17:34:06,581 - WARNING - Получена ошибка 429 для magnetized_cycle, повтор через 1 секунд (попытка 1).
2025-01-08 17:34:06,634 - WARNING - Получена ошибка 429 для magnetized_core, повтор через 1 секунд (попытка 1).
2025-01-08 17:34:06,635 - WARNING - Получена ошибка 429 для arcane_camisado, повтор через 1 секунд (попытка 3).
2025-01-08 17:34:06,655 - WARNING - Получена ошибка 429 для meso_t7_relic, повтор через 1 секунд (попытка 3).
2025-01-08 17:34:06,681 - WARNING - Получена ошибка 429 для arcane_truculence, повтор через 1 секунд (попытка 3).
2025-01-08 17:34:06,704 - WARNING - Получена ошибка 429 для mall_rotunda_simulacrum, повтор через 1 секунд (попытка 3).
2025-01-08 17:34:06,712 - WARNING - Получена ошибка 429 для trumna_prime_stock, повтор через 1 секунд (попытка 5).
2025-01-08 17:34:06,719 - WARNING - Получена ошибка 429 для arcane_impetus, повтор через 1 секунд (попытка 3).
2025-01-08 17:34:06,761 - ERROR - Не удалось получить данные для neo_c5_relic после 5 попыток. Превышено количество попыток.
2025-01-08 17:34:06,761 - WARNING - Получены пустые данные для предмета.
2025-01-08 17:34:06,764 - WARNING - Получена ошибка 429 для magnetic_strafe, повтор через 1 секунд (попытка 2).
2025-01-08 17:34:06,764 - WARNING - Получена ошибка 429 для axi_t12_relic, повтор через 1 секунд (попытка 4).
2025-01-08 17:34:06,791 - INFO - Успешно получены данные для предмета: spectral_serration
2025-01-08 17:34:06,791 - ERROR - Ошибка при обработке результата: 'url_name'
Traceback (most recent call last):
  File "C:\Users\New\Documents\GitHub\WarframeMarketAnalysys\WarframeMarketDataCollector.py", line 114, in main
    all_items_data[item_data['url_name']] = item_data
                   ~~~~~~~~~^^^^^^^^^^^^
KeyError: 'url_name'
2025-01-08 17:34:06,867 - WARNING - Получена ошибка 429 для reconifex_set, повтор через 1 секунд (попытка 1).
2025-01-08 17:34:06,877 - INFO - Успешно получены данные для предмета: höllvanian_courtyard_simulacrum
2025-01-08 17:34:06,878 - ERROR - Ошибка при обработке результата: 'url_name'
Traceback (most recent call last):
  File "C:\Users\New\Documents\GitHub\WarframeMarketAnalysys\WarframeMarketDataCollector.py", line 114, in main
    all_items_data[item_data['url_name']] = item_data
                   ~~~~~~~~~^^^^^^^^^^^^
KeyError: 'url_name'
2025-01-08 17:34:06,885 - WARNING - Получена ошибка 429 для neo_w2_relic, повтор через 1 секунд (попытка 4).
2025-01-08 17:34:06,895 - WARNING - Получена ошибка 429 для reconifex_barrel, повтор через 1 секунд (попытка 1).
2025-01-08 17:34:06,921 - WARNING - Получена ошибка 429 для melee_doughty, повтор через 1 секунд (попытка 3).
2025-01-08 17:34:06,961 - WARNING - Получена ошибка 429 для neo_g8_relic, повтор через 1 секунд (попытка 4).
2025-01-08 17:34:06,991 - WARNING - Получена ошибка 429 для arcane_crepuscular, повтор через 1 секунд (попытка 3).
2025-01-08 17:34:06,996 - WARNING - Получена ошибка 429 для reconifex_receiver, повтор через 1 секунд (попытка 1).
2025-01-08 17:34:07,012 - INFO - Успешно получены данные для предмета: arcane_bellicose
2025-01-08 17:34:07,012 - ERROR - Ошибка при обработке результата: 'url_name'
Traceback (most recent call last):
  File "C:\Users\New\Documents\GitHub\WarframeMarketAnalysys\WarframeMarketDataCollector.py", line 114, in main
    all_items_data[item_data['url_name']] = item_data
                   ~~~~~~~~~^^^^^^^^^^^^
KeyError: 'url_name'
2025-01-08 17:34:07,035 - WARNING - Получена ошибка 429 для quassus_prime_blueprint, повтор через 1 секунд (попытка 5).
2025-01-08 17:34:07,060 - WARNING - Получена ошибка 429 для magnetic_welt, повтор через 1 секунд (попытка 2).
2025-01-08 17:34:07,083 - WARNING - Получена ошибка 429 для tech_titan_electronics_store, повтор через 1 секунд (попытка 3).
2025-01-08 17:34:07,098 - WARNING - Получена ошибка 429 для neo_l4_relic, повтор через 1 секунд (попытка 4).
2025-01-08 17:34:07,103 - WARNING - Получена ошибка 429 для reconifex_stock, повтор через 1 секунд (попытка 1).
2025-01-08 17:34:07,117 - ERROR - Не удалось получить данные для xaku_prime_set после 5 попыток. Превышено количество попыток.
2025-01-08 17:34:07,118 - WARNING - Получены пустые данные для предмета.
2025-01-08 17:34:07,164 - WARNING - Получена ошибка 429 для trumna_prime_blueprint, повтор через 1 секунд (попытка 5).
2025-01-08 17:34:07,213 - INFO - Успешно получены данные для предмета: primary_acuity
2025-01-08 17:34:07,213 - ERROR - Ошибка при обработке результата: 'url_name'
Traceback (most recent call last):
  File "C:\Users\New\Documents\GitHub\WarframeMarketAnalysys\WarframeMarketDataCollector.py", line 114, in main
    all_items_data[item_data['url_name']] = item_data
                   ~~~~~~~~~^^^^^^^^^^^^
KeyError: 'url_name'
2025-01-08 17:34:07,216 - WARNING - Получена ошибка 429 для magnetic_claws, повтор через 1 секунд (попытка 2).
2025-01-08 17:34:07,226 - WARNING - Получена ошибка 429 для vesper_77_set, повтор через 1 секунд (попытка 1).
2025-01-08 17:34:07,235 - WARNING - Получена ошибка 429 для höllvania_central_mall_subway, повтор через 1 секунд (попытка 3).
2025-01-08 17:34:07,237 - WARNING - Получена ошибка 429 для quassus_prime_set, повтор через 1 секунд (попытка 5).
2025-01-08 17:34:07,237 - WARNING - Получена ошибка 429 для quassus_prime_blade, повтор через 1 секунд (попытка 5).
2025-01-08 17:34:07,272 - ERROR - Не удалось получить данные для trumna_prime_set после 5 попыток. Превышено количество попыток.
2025-01-08 17:34:07,272 - WARNING - Получены пустые данные для предмета.
2025-01-08 17:34:07,327 - WARNING - Получена ошибка 429 для vesper_77_barrel, повтор через 1 секунд (попытка 1).
2025-01-08 17:34:07,327 - WARNING - Получена ошибка 429 для quassus_prime_handle, повтор через 1 секунд (попытка 5).
2025-01-08 17:34:07,330 - WARNING - Получена ошибка 429 для magnetic_capacity, повтор через 1 секунд (попытка 2).
2025-01-08 17:34:07,345 - WARNING - Получена ошибка 429 для lith_m9_relic, повтор через 1 секунд (попытка 4).
2025-01-08 17:34:07,356 - WARNING - Получена ошибка 429 для vesper_77_receiver, повтор через 1 секунд (попытка 1).
2025-01-08 17:34:07,364 - ERROR - Не удалось получить данные для xaku_prime_systems_blueprint после 5 попыток. Превышено количество попыток.
2025-01-08 17:34:07,364 - WARNING - Получены пустые данные для предмета.
2025-01-08 17:34:07,377 - WARNING - Получена ошибка 429 для höllvanian_tenements_in_summer, повтор через 1 секунд (попытка 3).
2025-01-08 17:34:07,416 - INFO - Успешно получены данные для предмета: lith_n16_relic
2025-01-08 17:34:07,416 - ERROR - Ошибка при обработке результата: 'url_name'
Traceback (most recent call last):
  File "C:\Users\New\Documents\GitHub\WarframeMarketAnalysys\WarframeMarketDataCollector.py", line 114, in main
    all_items_data[item_data['url_name']] = item_data
                   ~~~~~~~~~^^^^^^^^^^^^
KeyError: 'url_name'
2025-01-08 17:34:07,460 - WARNING - Получена ошибка 429 для merciless_gunfight, повтор через 1 секунд (попытка 2).
2025-01-08 17:34:07,474 - WARNING - Получена ошибка 429 для höllvanian_intersection_in_winter, повтор через 1 секунд (попытка 3).
2025-01-08 17:34:07,484 - WARNING - Получена ошибка 429 для höllvanian_historic_quarter_in_spring, повтор через 1 секунд (попытка 3).
2025-01-08 17:34:07,485 - WARNING - Получена ошибка 429 для vesper_77_handle, повтор через 1 секунд (попытка 1).
2025-01-08 17:34:07,524 - INFO - Успешно получены данные для предмета: höllvanian_old_town_in_fall
2025-01-08 17:34:07,524 - ERROR - Ошибка при обработке результата: 'url_name'
Traceback (most recent call last):
  File "C:\Users\New\Documents\GitHub\WarframeMarketAnalysys\WarframeMarketDataCollector.py", line 114, in main
    all_items_data[item_data['url_name']] = item_data
                   ~~~~~~~~~^^^^^^^^^^^^
KeyError: 'url_name'
2025-01-08 17:34:07,546 - WARNING - Получена ошибка 429 для secondary_enervate, повтор через 1 секунд (попытка 4).
2025-01-08 17:34:07,578 - ERROR - Не удалось получить данные для trumna_prime_barrel после 5 попыток. Превышено количество попыток.
2025-01-08 17:34:07,579 - WARNING - Получены пустые данные для предмета.
2025-01-08 17:34:07,588 - WARNING - Получена ошибка 429 для magnetic_rush, повтор через 1 секунд (попытка 2).
2025-01-08 17:34:07,598 - WARNING - Получена ошибка 429 для lith_x1_relic, повтор через 1 секунд (попытка 4).
2025-01-08 17:34:07,626 - WARNING - Получена ошибка 429 для central_mall_backroom, повтор через 1 секунд (попытка 3).
2025-01-08 17:34:07,637 - WARNING - Получена ошибка 429 для worthy_comradery, повтор через 1 секунд (попытка 2).
2025-01-08 17:34:07,637 - WARNING - Получена ошибка 429 для orbit_arcade, повтор через 1 секунд (попытка 3).
2025-01-08 17:34:07,638 - WARNING - Получена ошибка 429 для summoner’s_wrath, повтор через 1 секунд (попытка 2).
2025-01-08 17:34:07,640 - WARNING - Получена ошибка 429 для axi_a19_relic, повтор через 1 секунд (попытка 5).
2025-01-08 17:34:07,679 - WARNING - Получена ошибка 429 для axi_g14_relic, повтор через 1 секунд (попытка 5).
2025-01-08 17:34:07,683 - WARNING - Получена ошибка 429 для magnetized_cycle, повтор через 1 секунд (попытка 2).
2025-01-08 17:34:07,716 - ERROR - Не удалось получить данные для trumna_prime_stock после 5 попыток. Превышено количество попыток.
2025-01-08 17:34:07,716 - WARNING - Получены пустые данные для предмета.
2025-01-08 17:34:07,731 - WARNING - Получена ошибка 429 для arcane_camisado, повтор через 1 секунд (попытка 4).
2025-01-08 17:34:07,745 - WARNING - Получена ошибка 429 для magnetized_core, повтор через 1 секунд (попытка 2).
2025-01-08 17:34:07,777 - WARNING - Получена ошибка 429 для meso_t7_relic, повтор через 1 секунд (попытка 4).
2025-01-08 17:34:07,796 - WARNING - Получена ошибка 429 для arcane_truculence, повтор через 1 секунд (попытка 4).
2025-01-08 17:34:07,809 - WARNING - Получена ошибка 429 для arcane_impetus, повтор через 1 секунд (попытка 4).
2025-01-08 17:34:07,824 - WARNING - Получена ошибка 429 для mall_rotunda_simulacrum, повтор через 1 секунд (попытка 4).
2025-01-08 17:34:07,909 - WARNING - Получена ошибка 429 для magnetic_strafe, повтор через 1 секунд (попытка 3).
2025-01-08 17:34:07,920 - INFO - Успешно получены данные для предмета: axi_t12_relic
2025-01-08 17:34:07,920 - ERROR - Ошибка при обработке результата: 'url_name'
Traceback (most recent call last):
  File "C:\Users\New\Documents\GitHub\WarframeMarketAnalysys\WarframeMarketDataCollector.py", line 114, in main
    all_items_data[item_data['url_name']] = item_data
                   ~~~~~~~~~^^^^^^^^^^^^
KeyError: 'url_name'
2025-01-08 17:34:07,972 - WARNING - Получена ошибка 429 для reconifex_set, повтор через 1 секунд (попытка 2).
2025-01-08 17:34:07,994 - WARNING - Получена ошибка 429 для neo_w2_relic, повтор через 1 секунд (попытка 5).
2025-01-08 17:34:08,017 - WARNING - Получена ошибка 429 для reconifex_barrel, повтор через 1 секунд (попытка 2).
2025-01-08 17:34:08,038 - ERROR - Не удалось получить данные для quassus_prime_blueprint после 5 попыток. Превышено количество попыток.
2025-01-08 17:34:08,038 - WARNING - Получены пустые данные для предмета.
2025-01-08 17:34:08,055 - WARNING - Получена ошибка 429 для neo_g8_relic, повтор через 1 секунд (попытка 5).
2025-01-08 17:34:08,097 - WARNING - Получена ошибка 429 для arcane_crepuscular, повтор через 1 секунд (попытка 4).
2025-01-08 17:34:08,117 - WARNING - Получена ошибка 429 для reconifex_receiver, повтор через 1 секунд (попытка 2).
2025-01-08 17:34:08,147 - WARNING - Получена ошибка 429 для magnetic_welt, повтор через 1 секунд (попытка 3).
2025-01-08 17:34:08,177 - ERROR - Не удалось получить данные для trumna_prime_blueprint после 5 попыток. Превышено количество попыток.
2025-01-08 17:34:08,177 - WARNING - Получены пустые данные для предмета.
2025-01-08 17:34:08,235 - WARNING - Получена ошибка 429 для reconifex_stock, повтор через 1 секунд (попытка 2).
2025-01-08 17:34:08,239 - INFO - Успешно получены данные для предмета: tech_titan_electronics_store
2025-01-08 17:34:08,239 - ERROR - Не удалось получить данные для quassus_prime_set после 5 попыток. Превышено количество попыток.
2025-01-08 17:34:08,239 - ERROR - Не удалось получить данные для quassus_prime_blade после 5 попыток. Превышено количество попыток.
2025-01-08 17:34:08,239 - ERROR - Ошибка при обработке результата: 'url_name'
Traceback (most recent call last):
  File "C:\Users\New\Documents\GitHub\WarframeMarketAnalysys\WarframeMarketDataCollector.py", line 114, in main
    all_items_data[item_data['url_name']] = item_data
                   ~~~~~~~~~^^^^^^^^^^^^
KeyError: 'url_name'
2025-01-08 17:34:08,239 - WARNING - Получены пустые данные для предмета.
2025-01-08 17:34:08,239 - WARNING - Получены пустые данные для предмета.
2025-01-08 17:34:08,329 - WARNING - Получена ошибка 429 для magnetic_claws, повтор через 1 секунд (попытка 3).
2025-01-08 17:34:08,329 - ERROR - Не удалось получить данные для quassus_prime_handle после 5 попыток. Превышено количество попыток.
2025-01-08 17:34:08,329 - WARNING - Получены пустые данные для предмета.
2025-01-08 17:34:08,330 - WARNING - Получена ошибка 429 для vesper_77_set, повтор через 1 секунд (попытка 2).
2025-01-08 17:34:08,339 - WARNING - Получена ошибка 429 для höllvania_central_mall_subway, повтор через 1 секунд (попытка 4).
2025-01-08 17:34:08,435 - WARNING - Получена ошибка 429 для vesper_77_barrel, повтор через 1 секунд (попытка 2).
2025-01-08 17:34:08,453 - INFO - Успешно получены данные для предмета: melee_doughty
2025-01-08 17:34:08,453 - ERROR - Ошибка при обработке результата: 'url_name'
Traceback (most recent call last):
  File "C:\Users\New\Documents\GitHub\WarframeMarketAnalysys\WarframeMarketDataCollector.py", line 114, in main
    all_items_data[item_data['url_name']] = item_data
                   ~~~~~~~~~^^^^^^^^^^^^
KeyError: 'url_name'
2025-01-08 17:34:08,472 - WARNING - Получена ошибка 429 для vesper_77_receiver, повтор через 1 секунд (попытка 2).
2025-01-08 17:34:08,512 - WARNING - Получена ошибка 429 для neo_l4_relic, повтор через 1 секунд (попытка 5).
2025-01-08 17:34:08,522 - WARNING - Получена ошибка 429 для lith_m9_relic, повтор через 1 секунд (попытка 5).
2025-01-08 17:34:08,548 - INFO - Успешно получены данные для предмета: magnetic_capacity
2025-01-08 17:34:08,548 - ERROR - Ошибка при обработке результата: 'url_name'
Traceback (most recent call last):
  File "C:\Users\New\Documents\GitHub\WarframeMarketAnalysys\WarframeMarketDataCollector.py", line 114, in main
    all_items_data[item_data['url_name']] = item_data
                   ~~~~~~~~~^^^^^^^^^^^^
KeyError: 'url_name'
2025-01-08 17:34:08,591 - WARNING - Получена ошибка 429 для vesper_77_handle, повтор через 1 секунд (попытка 2).
2025-01-08 17:34:08,605 - WARNING - Получена ошибка 429 для höllvanian_historic_quarter_in_spring, повтор через 1 секунд (попытка 4).
2025-01-08 17:34:08,613 - WARNING - Получена ошибка 429 для höllvanian_intersection_in_winter, повтор через 1 секунд (попытка 4).
2025-01-08 17:34:08,621 - WARNING - Получена ошибка 429 для secondary_enervate, повтор через 1 секунд (попытка 5).
2025-01-08 17:34:08,654 - ERROR - Не удалось получить данные для axi_a19_relic после 5 попыток. Превышено количество попыток.
2025-01-08 17:34:08,654 - WARNING - Получены пустые данные для предмета.
2025-01-08 17:34:08,674 - WARNING - Получена ошибка 429 для magnetic_rush, повтор через 1 секунд (попытка 3).
2025-01-08 17:34:08,684 - ERROR - Не удалось получить данные для axi_g14_relic после 5 попыток. Превышено количество попыток.
2025-01-08 17:34:08,684 - WARNING - Получены пустые данные для предмета.
2025-01-08 17:34:08,687 - WARNING - Получена ошибка 429 для merciless_gunfight, повтор через 1 секунд (попытка 3).
2025-01-08 17:34:08,732 - WARNING - Получена ошибка 429 для summoner’s_wrath, повтор через 1 секунд (попытка 3).
2025-01-08 17:34:08,741 - WARNING - Получена ошибка 429 для central_mall_backroom, повтор через 1 секунд (попытка 4).
2025-01-08 17:34:08,744 - WARNING - Получена ошибка 429 для worthy_comradery, повтор через 1 секунд (попытка 3).
2025-01-08 17:34:08,790 - WARNING - Получена ошибка 429 для magnetized_cycle, повтор через 1 секунд (попытка 3).
2025-01-08 17:34:08,874 - INFO - Успешно получены данные для предмета: arcane_camisado
2025-01-08 17:34:08,874 - ERROR - Ошибка при обработке результата: 'url_name'
Traceback (most recent call last):
  File "C:\Users\New\Documents\GitHub\WarframeMarketAnalysys\WarframeMarketDataCollector.py", line 114, in main
    all_items_data[item_data['url_name']] = item_data
                   ~~~~~~~~~^^^^^^^^^^^^
KeyError: 'url_name'
2025-01-08 17:34:08,896 - WARNING - Получена ошибка 429 для meso_t7_relic, повтор через 1 секунд (попытка 5).
2025-01-08 17:34:08,900 - WARNING - Получена ошибка 429 для arcane_impetus, повтор через 1 секунд (попытка 5).
2025-01-08 17:34:08,903 - WARNING - Получена ошибка 429 для magnetized_core, повтор через 1 секунд (попытка 3).
2025-01-08 17:34:08,903 - WARNING - Получена ошибка 429 для arcane_truculence, повтор через 1 секунд (попытка 5).
2025-01-08 17:34:08,907 - INFO - Успешно получены данные для предмета: lith_x1_relic
2025-01-08 17:34:08,907 - ERROR - Ошибка при обработке результата: 'url_name'
Traceback (most recent call last):
  File "C:\Users\New\Documents\GitHub\WarframeMarketAnalysys\WarframeMarketDataCollector.py", line 114, in main
    all_items_data[item_data['url_name']] = item_data
                   ~~~~~~~~~^^^^^^^^^^^^
KeyError: 'url_name'
2025-01-08 17:34:08,915 - WARNING - Получена ошибка 429 для höllvanian_tenements_in_summer, повтор через 1 секунд (попытка 4).
2025-01-08 17:34:08,943 - WARNING - Получена ошибка 429 для mall_rotunda_simulacrum, повтор через 1 секунд (попытка 5).
2025-01-08 17:34:09,005 - ERROR - Не удалось получить данные для neo_w2_relic после 5 попыток. Превышено количество попыток.
2025-01-08 17:34:09,005 - WARNING - Получены пустые данные для предмета.
2025-01-08 17:34:09,030 - WARNING - Получена ошибка 429 для magnetic_strafe, повтор через 1 секунд (попытка 4).
2025-01-08 17:34:09,050 - WARNING - Получена ошибка 429 для orbit_arcade, повтор через 1 секунд (попытка 4).
2025-01-08 17:34:09,067 - ERROR - Не удалось получить данные для neo_g8_relic после 5 попыток. Превышено количество попыток.
2025-01-08 17:34:09,067 - WARNING - Получены пустые данные для предмета.
2025-01-08 17:34:09,080 - WARNING - Получена ошибка 429 для reconifex_set, повтор через 1 секунд (попытка 3).
2025-01-08 17:34:09,142 - WARNING - Получена ошибка 429 для reconifex_barrel, повтор через 1 секунд (попытка 3).
2025-01-08 17:34:09,221 - INFO - Успешно получены данные для предмета: arcane_crepuscular
2025-01-08 17:34:09,221 - ERROR - Ошибка при обработке результата: 'url_name'
Traceback (most recent call last):
  File "C:\Users\New\Documents\GitHub\WarframeMarketAnalysys\WarframeMarketDataCollector.py", line 114, in main
    all_items_data[item_data['url_name']] = item_data
                   ~~~~~~~~~^^^^^^^^^^^^
KeyError: 'url_name'
2025-01-08 17:34:09,225 - WARNING - Получена ошибка 429 для reconifex_receiver, повтор через 1 секунд (попытка 3).
2025-01-08 17:34:09,243 - WARNING - Получена ошибка 429 для magnetic_welt, повтор через 1 секунд (попытка 4).
2025-01-08 17:34:09,409 - WARNING - Получена ошибка 429 для reconifex_stock, повтор через 1 секунд (попытка 3).
2025-01-08 17:34:09,422 - WARNING - Получена ошибка 429 для vesper_77_set, повтор через 1 секунд (попытка 3).
2025-01-08 17:34:09,427 - WARNING - Получена ошибка 429 для höllvania_central_mall_subway, повтор через 1 секунд (попытка 5).
2025-01-08 17:34:09,473 - WARNING - Получена ошибка 429 для magnetic_claws, повтор через 1 секунд (попытка 4).
2025-01-08 17:34:09,515 - ERROR - Не удалось получить данные для neo_l4_relic после 5 попыток. Превышено количество попыток.
2025-01-08 17:34:09,515 - WARNING - Получены пустые данные для предмета.
2025-01-08 17:34:09,531 - ERROR - Не удалось получить данные для lith_m9_relic после 5 попыток. Превышено количество попыток.
2025-01-08 17:34:09,531 - WARNING - Получены пустые данные для предмета.
2025-01-08 17:34:09,589 - WARNING - Получена ошибка 429 для vesper_77_receiver, повтор через 1 секунд (попытка 3).
2025-01-08 17:34:09,624 - ERROR - Не удалось получить данные для secondary_enervate после 5 попыток. Превышено количество попыток.
2025-01-08 17:34:09,624 - WARNING - Получены пустые данные для предмета.
2025-01-08 17:34:09,645 - INFO - Успешно получены данные для предмета: vesper_77_barrel
2025-01-08 17:34:09,645 - ERROR - Ошибка при обработке результата: 'url_name'
Traceback (most recent call last):
  File "C:\Users\New\Documents\GitHub\WarframeMarketAnalysys\WarframeMarketDataCollector.py", line 114, in main
    all_items_data[item_data['url_name']] = item_data
                   ~~~~~~~~~^^^^^^^^^^^^
KeyError: 'url_name'
2025-01-08 17:34:09,684 - WARNING - Получена ошибка 429 для vesper_77_handle, повтор через 1 секунд (попытка 3).
2025-01-08 17:34:09,715 - WARNING - Получена ошибка 429 для höllvanian_historic_quarter_in_spring, повтор через 1 секунд (попытка 5).
2025-01-08 17:34:09,741 - WARNING - Получена ошибка 429 для höllvanian_intersection_in_winter, повтор через 1 секунд (попытка 5).
2025-01-08 17:34:09,786 - WARNING - Получена ошибка 429 для magnetic_rush, повтор через 1 секунд (попытка 4).
2025-01-08 17:34:09,806 - WARNING - Получена ошибка 429 для merciless_gunfight, повтор через 1 секунд (попытка 4).
2025-01-08 17:34:09,843 - INFO - Успешно получены данные для предмета: worthy_comradery
2025-01-08 17:34:09,843 - ERROR - Ошибка при обработке результата: 'url_name'
Traceback (most recent call last):
  File "C:\Users\New\Documents\GitHub\WarframeMarketAnalysys\WarframeMarketDataCollector.py", line 114, in main
    all_items_data[item_data['url_name']] = item_data
                   ~~~~~~~~~^^^^^^^^^^^^
KeyError: 'url_name'
2025-01-08 17:34:09,858 - WARNING - Получена ошибка 429 для central_mall_backroom, повтор через 1 секунд (попытка 5).
2025-01-08 17:34:09,902 - ERROR - Не удалось получить данные для meso_t7_relic после 5 попыток. Превышено количество попыток.
2025-01-08 17:34:09,902 - ERROR - Не удалось получить данные для arcane_impetus после 5 попыток. Превышено количество попыток.
2025-01-08 17:34:09,902 - WARNING - Получены пустые данные для предмета.
2025-01-08 17:34:09,902 - WARNING - Получены пустые данные для предмета.
2025-01-08 17:34:09,917 - ERROR - Не удалось получить данные для arcane_truculence после 5 попыток. Превышено количество попыток.
2025-01-08 17:34:09,917 - WARNING - Получены пустые данные для предмета.
2025-01-08 17:34:09,938 - WARNING - Получена ошибка 429 для magnetized_cycle, повтор через 1 секунд (попытка 4).
2025-01-08 17:34:09,947 - ERROR - Не удалось получить данные для mall_rotunda_simulacrum после 5 попыток. Превышено количество попыток.
2025-01-08 17:34:09,947 - WARNING - Получены пустые данные для предмета.
2025-01-08 17:34:10,026 - WARNING - Получена ошибка 429 для magnetized_core, повтор через 1 секунд (попытка 4).
2025-01-08 17:34:10,035 - WARNING - Получена ошибка 429 для höllvanian_tenements_in_summer, повтор через 1 секунд (попытка 5).
2025-01-08 17:34:10,150 - WARNING - Получена ошибка 429 для magnetic_strafe, повтор через 1 секунд (попытка 5).
2025-01-08 17:34:10,181 - INFO - Успешно получены данные для предмета: summoner’s_wrath
2025-01-08 17:34:10,181 - ERROR - Ошибка при обработке результата: 'url_name'
Traceback (most recent call last):
  File "C:\Users\New\Documents\GitHub\WarframeMarketAnalysys\WarframeMarketDataCollector.py", line 114, in main
    all_items_data[item_data['url_name']] = item_data
                   ~~~~~~~~~^^^^^^^^^^^^
KeyError: 'url_name'
2025-01-08 17:34:10,187 - WARNING - Получена ошибка 429 для orbit_arcade, повтор через 1 секунд (попытка 5).
2025-01-08 17:34:10,201 - INFO - Успешно получены данные для предмета: reconifex_set
2025-01-08 17:34:10,201 - ERROR - Ошибка при обработке результата: 'url_name'
Traceback (most recent call last):
  File "C:\Users\New\Documents\GitHub\WarframeMarketAnalysys\WarframeMarketDataCollector.py", line 114, in main
    all_items_data[item_data['url_name']] = item_data
                   ~~~~~~~~~^^^^^^^^^^^^
KeyError: 'url_name'
2025-01-08 17:34:10,362 - WARNING - Получена ошибка 429 для reconifex_receiver, повтор через 1 секунд (попытка 4).
2025-01-08 17:34:10,440 - ERROR - Не удалось получить данные для höllvania_central_mall_subway после 5 попыток. Превышено количество попыток.
2025-01-08 17:34:10,440 - WARNING - Получены пустые данные для предмета.
2025-01-08 17:34:10,511 - WARNING - Получена ошибка 429 для reconifex_stock, повтор через 1 секунд (попытка 4).
2025-01-08 17:34:10,542 - WARNING - Получена ошибка 429 для vesper_77_set, повтор через 1 секунд (попытка 4).
2025-01-08 17:34:10,542 - WARNING - Получена ошибка 429 для reconifex_barrel, повтор через 1 секунд (попытка 4).
2025-01-08 17:34:10,598 - WARNING - Получена ошибка 429 для magnetic_claws, повтор через 1 секунд (попытка 5).
2025-01-08 17:34:10,670 - INFO - Успешно получены данные для предмета: magnetic_welt
2025-01-08 17:34:10,670 - ERROR - Ошибка при обработке результата: 'url_name'
Traceback (most recent call last):
  File "C:\Users\New\Documents\GitHub\WarframeMarketAnalysys\WarframeMarketDataCollector.py", line 114, in main
    all_items_data[item_data['url_name']] = item_data
                   ~~~~~~~~~^^^^^^^^^^^^
KeyError: 'url_name'
2025-01-08 17:34:10,687 - WARNING - Получена ошибка 429 для vesper_77_receiver, повтор через 1 секунд (попытка 4).
2025-01-08 17:34:10,730 - ERROR - Не удалось получить данные для höllvanian_historic_quarter_in_spring после 5 попыток. Превышено количество попыток.
2025-01-08 17:34:10,730 - WARNING - Получены пустые данные для предмета.
2025-01-08 17:34:10,746 - ERROR - Не удалось получить данные для höllvanian_intersection_in_winter после 5 попыток. Превышено количество попыток.
2025-01-08 17:34:10,746 - WARNING - Получены пустые данные для предмета.
2025-01-08 17:34:10,824 - WARNING - Получена ошибка 429 для vesper_77_handle, повтор через 1 секунд (попытка 4).
2025-01-08 17:34:10,868 - ERROR - Не удалось получить данные для central_mall_backroom после 5 попыток. Превышено количество попыток.
2025-01-08 17:34:10,869 - WARNING - Получены пустые данные для предмета.
2025-01-08 17:34:10,894 - WARNING - Получена ошибка 429 для magnetic_rush, повтор через 1 секунд (попытка 5).
2025-01-08 17:34:10,909 - INFO - Успешно получены данные для предмета: merciless_gunfight
2025-01-08 17:34:10,909 - ERROR - Ошибка при обработке результата: 'url_name'
Traceback (most recent call last):
  File "C:\Users\New\Documents\GitHub\WarframeMarketAnalysys\WarframeMarketDataCollector.py", line 114, in main
    all_items_data[item_data['url_name']] = item_data
                   ~~~~~~~~~^^^^^^^^^^^^
KeyError: 'url_name'
2025-01-08 17:34:11,039 - ERROR - Не удалось получить данные для höllvanian_tenements_in_summer после 5 попыток. Превышено количество попыток.
2025-01-08 17:34:11,039 - WARNING - Получены пустые данные для предмета.
2025-01-08 17:34:11,085 - WARNING - Получена ошибка 429 для magnetized_cycle, повтор через 1 секунд (попытка 5).
2025-01-08 17:34:11,161 - ERROR - Не удалось получить данные для magnetic_strafe после 5 попыток. Превышено количество попыток.
2025-01-08 17:34:11,162 - WARNING - Получены пустые данные для предмета.
2025-01-08 17:34:11,193 - ERROR - Не удалось получить данные для orbit_arcade после 5 попыток. Превышено количество попыток.
2025-01-08 17:34:11,193 - WARNING - Получены пустые данные для предмета.
2025-01-08 17:34:11,323 - INFO - Успешно получены данные для предмета: magnetized_core
2025-01-08 17:34:11,323 - ERROR - Ошибка при обработке результата: 'url_name'
Traceback (most recent call last):
  File "C:\Users\New\Documents\GitHub\WarframeMarketAnalysys\WarframeMarketDataCollector.py", line 114, in main
    all_items_data[item_data['url_name']] = item_data
                   ~~~~~~~~~^^^^^^^^^^^^
KeyError: 'url_name'
2025-01-08 17:34:11,559 - WARNING - Получена ошибка 429 для reconifex_receiver, повтор через 1 секунд (попытка 5).
2025-01-08 17:34:11,614 - ERROR - Не удалось получить данные для magnetic_claws после 5 попыток. Превышено количество попыток.
2025-01-08 17:34:11,614 - WARNING - Получены пустые данные для предмета.
2025-01-08 17:34:11,661 - WARNING - Получена ошибка 429 для reconifex_barrel, повтор через 1 секунд (попытка 5).
2025-01-08 17:34:11,666 - WARNING - Получена ошибка 429 для vesper_77_set, повтор через 1 секунд (попытка 5).
2025-01-08 17:34:11,667 - INFO - Успешно получены данные для предмета: reconifex_stock
2025-01-08 17:34:11,667 - ERROR - Ошибка при обработке результата: 'url_name'
Traceback (most recent call last):
  File "C:\Users\New\Documents\GitHub\WarframeMarketAnalysys\WarframeMarketDataCollector.py", line 114, in main
    all_items_data[item_data['url_name']] = item_data
                   ~~~~~~~~~^^^^^^^^^^^^
KeyError: 'url_name'
2025-01-08 17:34:11,768 - WARNING - Получена ошибка 429 для vesper_77_receiver, повтор через 1 секунд (попытка 5).
2025-01-08 17:34:11,907 - ERROR - Не удалось получить данные для magnetic_rush после 5 попыток. Превышено количество попыток.
2025-01-08 17:34:11,907 - WARNING - Получены пустые данные для предмета.
2025-01-08 17:34:11,927 - INFO - Успешно получены данные для предмета: vesper_77_handle
2025-01-08 17:34:11,927 - ERROR - Ошибка при обработке результата: 'url_name'
Traceback (most recent call last):
  File "C:\Users\New\Documents\GitHub\WarframeMarketAnalysys\WarframeMarketDataCollector.py", line 114, in main
    all_items_data[item_data['url_name']] = item_data
                   ~~~~~~~~~^^^^^^^^^^^^
KeyError: 'url_name'
2025-01-08 17:34:12,093 - ERROR - Не удалось получить данные для magnetized_cycle после 5 попыток. Превышено количество попыток.
2025-01-08 17:34:12,093 - WARNING - Получены пустые данные для предмета.
2025-01-08 17:34:12,573 - ERROR - Не удалось получить данные для reconifex_receiver после 5 попыток. Превышено количество попыток.
2025-01-08 17:34:12,573 - WARNING - Получены пустые данные для предмета.
2025-01-08 17:34:12,666 - ERROR - Не удалось получить данные для reconifex_barrel после 5 попыток. Превышено количество попыток.
2025-01-08 17:34:12,666 - WARNING - Получены пустые данные для предмета.
2025-01-08 17:34:12,666 - ERROR - Не удалось получить данные для vesper_77_set после 5 попыток. Превышено количество попыток.
2025-01-08 17:34:12,666 - WARNING - Получены пустые данные для предмета.
2025-01-08 17:34:12,774 - ERROR - Не удалось получить данные для vesper_77_receiver после 5 попыток. Превышено количество попыток.
2025-01-08 17:34:12,774 - WARNING - Получены пустые данные для предмета.
2025-01-08 17:34:12,775 - INFO - Сбор данных завершен.
2025-01-08 17:34:12,778 - INFO - Время выполнения скрипта: 293.22 секунд
